<?xml version="1.0" ?>
<!-- =================================================================================== -->
<!-- |    This document was autogenerated by xacro from mybot.xacro                    | -->
<!-- |    EDITING THIS FILE BY HAND IS NOT RECOMMENDED                                 | -->
<!-- =================================================================================== -->
<!-- This is a URDF description file of a mobile robot, written by Muhammad Asem, m7mad3asem@gmail.com
It models: 1-Chassis with Caster Wheel 2-Left wheel 3-right Wheel  4-Kinect /-->
<robot name="myrobot" xmlns:xacro="http://www.ros.org/wiki/xacro">
  <!--  ++++++++++++++++++ Diff drive plugin++++++++++++++++++          /-->
  <gazebo>
    <plugin filename="libgazebo_ros_diff_drive.so" name="differential_drive_controller">
      <legacyMode>false</legacyMode>
      <alwaysOn>true</alwaysOn>
      <updateRate>20</updateRate>
      <leftJoint>left_wheel_hinge</leftJoint>
      <rightJoint>right_wheel_hinge</rightJoint>
      <wheelSeparation>0.4</wheelSeparation>
      <wheelDiameter>0.1</wheelDiameter>
      <torque>20</torque>
      <commandTopic>cmd_vel</commandTopic>
      <odometryTopic>odom</odometryTopic>
      <odometryFrame>odom</odometryFrame>
      <robotBaseFrame>chassis</robotBaseFrame>
    </plugin>
  </gazebo>
  <!--  +++++++++++++Chassis Orange color++++++++++++++++          /-->
  <gazebo reference="chassis">
    <material>Gazebo/Orange</material>
  </gazebo>
  <!--  ++++++++++++++++Left wheel Blue Color+++++++++++++++++++          /-->
  <gazebo reference="left_wheel">
    <material>Gazebo/Blue</material>
  </gazebo>
  <!--  +++++++++++++++Right wheel Blue Color+++++++++++++++++          /-->
  <gazebo reference="right_wheel">
    <material>Gazebo/Blue</material>
  </gazebo>
  <!--  ++++++++++++++++++Kinect Plugin+++++++++++++++++++          /-->
  <gazebo reference="camera_link">
    <sensor name="camera" type="depth">
      <always_on>1</always_on>
      <visualize>true</visualize>
      <camera>
        <horizontal_fov>1.047</horizontal_fov>
        <image>
          <width>640</width>
          <height>480</height>
          <format>R8G8B8</format>
        </image>
        <clip>
          <near>0.1</near>
          <far>100</far>
        </clip>
      </camera>
      <plugin filename="libgazebo_ros_openni_kinect.so" name="camera_controller">
        <alwaysOn>true</alwaysOn>
        <updateRate>10.0</updateRate>
        <cameraName>camera</cameraName>
        <frameName>camera_link</frameName>
        <imageTopicName>rgb/image_raw</imageTopicName>
        <depthImageTopicName>depth/image_raw</depthImageTopicName>
        <pointCloudTopicName>depth/points</pointCloudTopicName>
        <cameraInfoTopicName>rgb/camera_info</cameraInfoTopicName>
        <depthImageCameraInfoTopicName>depth/camera_info</depthImageCameraInfoTopicName>
        <pointCloudCutoff>0.4</pointCloudCutoff>
        <hackBaseline>0.07</hackBaseline>
        <distortionK1>0.0</distortionK1>
        <distortionK2>0.0</distortionK2>
        <distortionK3>0.0</distortionK3>
        <distortionT1>0.0</distortionT1>
        <distortionT2>0.0</distortionT2>
        <CxPrime>0.0</CxPrime>
        <Cx>0.0</Cx>
        <Cy>0.0</Cy>
        <focalLength>0.0</focalLength>
      </plugin>
    </sensor>
  </gazebo>
  <!-- +++++++++++++++++++++++Robot Definition+++++++++++++++++++++++++ /-->
  <!--Chassis & Caster Link /-->
  <link name="chassis">
    <visual name="chassis_visual">
      <origin rpy=" 0 0 0" xyz="0 0 0"/>
      <geometry>
        <cylinder length="0.04" radius="0.2"/>
      </geometry>
    </visual>
    <inertial>
      <mass value="10.0"/>
      <origin rpy=" 0 0 0" xyz="0 0 0"/>
      <inertia ixx="0.5" ixy="0" ixz="0" iyy="1.0" iyz="0" izz="0.1"/>
    </inertial>
    <collision name="collision">
      <geometry>
        <cylinder length="0.04" radius="0.2"/>
      </geometry>
    </collision>
    <collision name="caster_collision">
      <origin rpy=" 0 0 0" xyz="-0.2 0 -0.05"/>
      <geometry>
        <sphere radius="0.05"/>
      </geometry>
      <surface>
        <friction>
          <ode>
            <mu>0</mu>
            <mu2>0</mu2>
            <slip1>1.0</slip1>
            <slip2>1.0</slip2>
          </ode>
        </friction>
      </surface>
    </collision>
    <visual name="caster_visual">
      <origin rpy=" 0 0 0" xyz="-0.2 0 -0.05"/>
      <geometry>
        <sphere radius="0.05"/>
      </geometry>
    </visual>
  </link>
  <!-- ++++++++++++++++Left wheel+++++++++++++++++++++++++++++++ /-->
  <!--left wheel Joint /-->
  <joint name="left_wheel_hinge" type="continuous">
    <origin rpy="0 0 0" xyz="-0.11 0.2 0"/>
    <child link="left_wheel"/>
    <parent link="chassis"/>
    <axis rpy="0 0 0" xyz="0 1 0"/>
    <limit effort="100" velocity="100"/>
    <joint_properties damping="0.0" friction="0.0"/>
  </joint>
  <!--left wheel Link /-->
  <link name="left_wheel">
    <visual name="left_wheel_visual">
      <origin rpy="0 1.5707 1.5707" xyz="0 0 0"/>
      <geometry>
        <cylinder length="0.05" radius="0.1"/>
      </geometry>
    </visual>
    <collision name="collision">
      <origin rpy="0 1.5707 1.5707" xyz="0 0 0"/>
      <geometry>
        <cylinder length="0.05" radius="0.1"/>
      </geometry>
    </collision>
    <inertial>
      <origin rpy="0 1.5707 1.5707" xyz="0 0 0"/>
      <mass value="5"/>
      <cylinder_inertia h="0.05" m="5" r="0.1"/>
      <inertia ixx="1.0" ixy="0.0" ixz="0.0" iyy="1.0" iyz="0.0" izz="1.0"/>
    </inertial>
  </link>
  <!-- +++++++++++++++++++ Right Wheel +++++++++++++++++++++++++++++++++ /-->
  <!--Right wheel joint/-->
  <joint name="right_wheel_hinge" type="continuous">
    <origin rpy="0 0 0" xyz="0.11 -0.2 0"/>
    <child link="right_wheel"/>
    <parent link="chassis"/>
    <axis rpy="0 0 0" xyz="0 1 0"/>
    <limit effort="100" velocity="100"/>
    <joint_properties damping="0.0" friction="0.0"/>
  </joint>
  <!--Right Wheel link /-->
  <link name="right_wheel">
    <visual name="right_wheel_visual">
      <origin rpy="0 1.5707 1.5707" xyz="0 0 0"/>
      <geometry>
        <cylinder length="0.05" radius="0.1"/>
      </geometry>
    </visual>
    <collision name="collision">
      <origin rpy="0 1.5707 1.5707" xyz="0 0 0"/>
      <geometry>
        <cylinder length="0.05" radius="0.1"/>
      </geometry>
    </collision>
    <inertial>
      <origin rpy="0 1.5707 1.5707" xyz="0 0 0"/>
      <mass value="5"/>
      <cylinder_inertia h="0.05" m="5" r="0.1"/>
      <inertia ixx="1.0" ixy="0.0" ixz="0.0" iyy="1.0" iyz="0.0" izz="1.0"/>
    </inertial>
  </link>
  <!-- ++++++++++++++++++  Kinect  +++++++++++++++++++++++++++++ /-->
  <!--kinect joint /-->
  <joint name="kinect_joint" type="fixed">
    <origin rpy="0 0 0" xyz=".15 0 .05"/>
    <parent link="chassis"/>
    <child link="camera_link"/>
  </joint>
  <!--Kinect  Link /-->
  <link name="camera_link">
    <visual>
      <origin rpy="0 0 0" xyz="0 0 0.05"/>
      <geometry>
        <mesh filename="package://robot_description/meshes/kinect.dae"/>
      </geometry>
    </visual>
    <collision>
      <origin rpy="0 0 0" xyz="0 0 0"/>
      <geometry>
        <box size="0.1 0.1 0.1"/>
      </geometry>
    </collision>
    <inertial>
      <mass value="1e-5"/>
      <origin rpy="0 0 0" xyz="0 0 0"/>
      <inertia ixx="1e-6" ixy="0" ixz="0" iyy="1e-6" iyz="0" izz="1e-6"/>
    </inertial>
  </link>
  <!--  Kinect Optical Link and joints   /-->
  <joint name="kinect_optical_joint" type="fixed">
    <origin rpy="-1.5707 0 -1.5707" xyz="0 0 0"/>
    <!-- To invert the coordinates from image convention (Z is forward) to normal xyz /-->
    <parent link="camera_link"/>
    <child link="kinect_optical"/>
  </joint>
  <!--Virtual link to project the images to, and then flip it to us as its joint is flipped  /-->
  <link name="kinect_optical">
</link>
</robot>

