<?xml version="1.0"?>

<robot name="CoviRob" xmlns:xacro="http://www.ros.org/wiki/xacro">

 <xacro:include filename="$(find robot_description)/urdf/materials.xacro"/>
 <xacro:include filename="$(find robot_description)/urdf/mybot.gazebo"/>


  <link name="chassis">
      <inertial>
          <origin xyz="0.0 0.0 0.0" rpy="0.0 0.0 0.0"/>
          <mass value="10.0"/>
          <inertia ixx="0.5" ixy="1.0" ixz="0.1" iyy="0.0" iyz="0.0" izz="0.0"/>
      </inertial>
      <visual name="bais_chassis_v">
          <origin xyz="0.0 0.0 0.0" rpy="0.0 0.0 0.0"/>
          <geometry>
              <cylinder radius="0.2" length="0.04"/>
          </geometry>
          <material name="white"/>
      </visual>
      <collision name="bais_chassis_c">
          <origin xyz="0.0 0.0 0.0" rpy="0.0 0.0 0.0"/>
          <geometry>
             <cylinder radius="0.2" length="0.04"/>
          </geometry>
      </collision>

      <visual name="support_left_visual">
          <origin xyz="-0.11 0.145 -0.025" rpy="0.0 0.0 0.0"/>
          <geometry>
              <box size="0.02 0.02 0.02"/>
          </geometry>
      </visual>
      <collision name="support_left_collision">
          <origin xyz="-0.11 0.145 -0.025" rpy="0.0 0.0 0.0"/>
          <geometry>
              <box size="0.02 0.02 0.02"/>
          </geometry>
      </collision>

      <visual name="support_right_visual">
          <origin xyz="-0.11 -0.145 -0.025" rpy="0.0 0.0 0.0"/>
          <geometry>
              <box size="0.02 0.02 0.02"/>
          </geometry>
      </visual>
      <collision name="support_right_collision">
          <origin xyz="-0.11 -0.145 -0.025" rpy="0.0 0.0 0.0"/>
          <geometry>
              <box size="0.02 0.02 0.02"/>
          </geometry>
      </collision>
    
     <collision name='caster_collision'>
        <origin xyz="0.15 0 -0.05" rpy=" 0 0 0"/>

        <geometry>
            <sphere radius="0.05"/>
        </geometry>

        <surface>

            <friction>
            <ode>
                <mu>0</mu>
                <mu2>0</mu2>
                <slip1>1.0</slip1>
                <slip2>1.0</slip2>
            </ode>
            </friction>

        </surface>

 </collision>

 <visual name='caster_visual'>

     <origin xyz="0.15 0 -0.05" rpy=" 0 0 0"/>

     <geometry>
      <sphere radius="0.05"/>
     </geometry>

 </visual>


  </link>
  
  <!-- <link name="support_wheel">
            <inertial>
                <origin rpy="-1.57075 0 1.57075" xyz="-0.021 -0.021 0"/>
                <mass value="0.05"/>
                <inertia ixx="0.0" ixy="0.0" ixz="0.0" iyy="0.0" iyz="0.0" izz="0.0"/>
            </inertial>
            
			<visual>
				<origin rpy="-1.57075 0 1.57075" xyz="-0.021 -0.021 0"/>
				<geometry>
					<mesh filename="package://nox_description/meshes/support_wheel.STL" scale="0.0018 0.0018 0.0018"/>
				</geometry>
				<material name="transparent_grey"/>
			</visual>
            <collision>
                <origin rpy="-1.57075 0 1.57075" xyz="-0.021 -0.021 0"/>
				<geometry>
					<mesh filename="package://nox_description/meshes/support_wheel.STL" scale="0.0018 0.0018 0.0018"/>
				</geometry>
            </collision>
  </link>	 -->
			
  <!-- <joint name="base_link_to_support_wheel_right" type="fixed">
			<parent link="chassis"/>
			<child link="support_wheel"/>
			<origin xyz="0.17 0.0 0.09"/>
  </joint> -->

  <link name="motor_left">
      <inertial>
          <origin rpy="-1.57075 0 0" xyz="-0.02 -0.061 0"/>
          <mass value="3.0"/>
          <inertia ixx="0.1" ixy="0.1" ixz="0.1" iyy="0.0" iyz="0.0" izz="0.0"/>
      </inertial>
      <visual name="motor_left_visual">
          <origin rpy="-1.57075 0 0" xyz="-0.02 -0.061 0"/>
          <geometry>
              <!-- <cylinder radius="0.02" length="0.05"/> -->
              <mesh filename="package://robot_description/meshes/motor.STL" scale="0.001 0.001 0.001"/>
          </geometry>
          <material name="grey"/>
      </visual>
      <collision name="motor_collision">
          <origin rpy="-1.57075 0 0" xyz="-0.02 -0.061 0"/>
          <geometry>
              <!-- <cylinder radius="0.02" length="0.05"/> -->
              <mesh filename="package://robot_description/meshes/motor.STL" scale="0.001 0.001 0.001"/>
          </geometry>
      </collision>
  </link>


  <joint name="motorleft_to_bais" type="fixed">
      <origin xyz="-0.11 0.17 -0.035" rpy="0.0 0.0 0.0"/>
      <parent link="chassis"/>
      <child link="motor_left"/>
      <axis xyz="0.0 0.0 0.0"/>
      <limit lower="0.0" upper="0.0" effort="0.0" velocity="0.0"/>
  </joint>
  

  <link name="motor_right">
      <inertial>
          <origin rpy="-1.57075 0 3.14159" xyz="0.02 0.061 0"/>
          <mass value="3.0"/>
          <inertia ixx="0.1" ixy="0.1" ixz="0.1" iyy="0.0" iyz="0.0" izz="0.0"/>
      </inertial>
      <visual name="motor_left_visual">
          <origin rpy="-1.57075 0 3.14159" xyz="0.02 0.061 0"/>
          <geometry>
                <!-- <cylinder radius="0.02" length="0.05"/> -->
              <mesh filename="package://robot_description/meshes/motor.STL" scale="0.001 0.001 0.001"/>
          </geometry>
          <material name="grey"/>
      </visual>
      <collision name="motor_right_collision">
          <origin rpy="-1.57075 0 3.14159" xyz="0.02 0.061 0"/>
          <geometry>
              <!-- <cylinder radius="0.02" length="0.05"/> -->
              <mesh filename="package://robot_description/meshes/motor.STL" scale="0.001 0.001 0.001"/>
          </geometry>
      </collision>
  </link>

  <joint name="motorright_to_bais" type="fixed">
      <origin xyz="-0.11 -0.17 -0.035" rpy="0.0 0.0 0.0"/>
      <parent link="chassis"/>
      <child link="motor_right"/>
      <axis xyz="0.0 0.0 0.0"/>
      <limit lower="0.0" upper="0.0" effort="0.0" velocity="0.0"/>
      
  </joint>

  <link name="wheel_left">
      <inertial>
          <origin rpy="1.57075 0 0" xyz="-0.04 0.02 -0.04"/>
          <mass value="5.0"/>
          <cylinder_inertia m="5" r="0.1" h="0.05"/>
          <inertia ixx="1.0" ixy="1.0" ixz="1.0" iyy="0.0" iyz="0.0" izz="0.0"/>
      </inertial>
      <visual name="">
          <origin rpy="1.57075 0 0" xyz="-0.04 0.02 -0.04"/>
          <geometry>
              <mesh filename="package://nox_description/meshes/wheel.STL" scale="0.001 0.001 0.001"/>
              <!-- <cylinder radius="0.035" length="0.035"/> -->
          </geometry>
          <material name="black"/>
      </visual>
      <collision>
          <origin rpy="1.57075 0 0" xyz="-0.04 0.02 -0.04"/>
          <geometry>
              <!-- <cylinder radius="0.035" length="0.035"/> -->
              <mesh filename="package://robot_description/meshes/wheel.STL" scale="0.001 0.001 0.001"/>
          </geometry>
      </collision>
  </link>

  <joint name="wheel_left_to_motor" type="continuous">
      <origin xyz="0.0 0.023 -0.019" rpy="0.0 0.0 0.0"/>
      <parent link="motor_left"/>
      <child link="wheel_left"/>
      <axis xyz="0.0 1.0 0.0"/>
      <limit lower="0.0" upper="0.0" effort="100.0" velocity="100.0"/>
      <joint_properties damping="0.0" friction="0.0"/>
  </joint>

  <link name="wheel_right">
      <inertial>
          <origin rpy="1.57075 0 0" xyz="-0.04 0.02 -0.04"/>
          <mass value="5.0"/>
          <inertia ixx="1.0" ixy="1.0" ixz="1.0" iyy="0.0" iyz="0.0" izz="0.0"/>
          <cylinder_inertia m="5" r="0.1" h="0.05"/>
      </inertial>
      <visual name="">
          <origin rpy="1.57075 0 0" xyz="-0.04 0.02 -0.04"/>
          <geometry>
              <mesh filename="package://robot_description/meshes/wheel.STL" scale="0.001 0.001 0.001"/>
              <!-- <cylinder radius="0.035" length="0.035"/> -->
          </geometry>
          <material name="black"/>
      </visual>
      <collision>
          <origin rpy="1.57075 0 0" xyz="-0.04 0.02 -0.04"/>
          <geometry>
              <mesh filename="package://robot_description/meshes/wheel.STL" scale="0.001 0.001 0.001"/>
          </geometry>
      </collision>
  </link>

  <joint name="wheel_right_to_motor" type="continuous">
      <origin xyz="0.0 -0.023 -0.019" rpy="0.0 0.0 0.0"/>
      <parent link="motor_right"/>
      <child link="wheel_right"/>
      <axis xyz="0.0 1.0 0.0"/>
      <limit lower="0.0" upper="0.0" effort="100.0" velocity="100.0"/>
      <joint_properties damping="0.0" friction="0.0"/>
  </joint>

  <link name="kinect">
            <inertial>
                <origin rpy="0 0 1.57075" xyz="0.03 -0.14 0.04"/>
                <mass value="1.0"/>
                <inertia ixx="0.1" ixy="0.1" ixz="0.1" iyy="0.0" iyz="0.0" izz="0.0"/>
            </inertial>
			<visual>
				<origin rpy="0 0 1.57075" xyz="0.03 -0.14 0.04"/>
				<geometry>
					<mesh filename="package://nox_description/meshes/kinect_sensor.stl" scale="0.01 0.01 0.01"/>
				</geometry>
				<material name="black"/>
			</visual>
            <collision>
                <origin rpy="0 0 1.57075" xyz="0.03 -0.14 0.04"/>
				<geometry>
					<mesh filename="package://nox_description/meshes/kinect_sensor.stl" scale="0.01 0.01 0.01"/>
				</geometry>
				<material name="black"/>
            </collision>
	</link>

	<joint name="base_link_to_kinect" type="fixed">
			<parent link="chassis"/>
			<child link="kinect"/>
			<origin xyz="0.1 0.0 0.008"/>
			<axis xyz="0 0 0"/>
	</joint>	

</robot>